Workbook

Sheet README
A1: Momentra iPhone Physical Device + Backend Load Test Workbook
A2: Purpose | B2: Source of truth for Maestro-driven Android/iPhone input, backend load observation, and calculation reconciliation.
A3: Dataset | B3: 3,500 valid transactions: 1,167 Personal + 1,167 Group + 1,166 Business.
A4: Load strategy | B4: Transactions are interleaved Personal -> Group -> Business throughout a single-platform 3,500-row certification run.
A5: Devices | B5: Platform-isolated dataset: iPhone only. Use separate QA_* identities from the other platform.
A6: Correctness | B6: Expected_Summary and Group_Splits contain the expected totals/splits. Reconciliation is for pasted actual app/backend values.
A7: Performance | B7: Performance_Log includes checkpoints through 3,300 rows and formulas for degradation/error thresholds.
A8: Figma note | B8: QuickAdd labels in QuickAdd_Catalog are representative placeholders and marked CONFIRM_FROM_FIGMA because the Figma connector did not return readable labels in this session. Replace labels there/Transactions before final Maestro automation if exact UI text differs.
A9: Recommended execution | B9: Run 300-write pilot separately, then certify checkpoints at 100, 250, 500, 1,000, 1,500, 2,000, 2,500, 3,000, 3,100, 3,200, 3,300, 3,400, 3,500.
A10: Important | B10: Main dataset contains only valid writes. Negative/invalid/idempotency/concurrency cases remain in Test_Cases.

Sheet Config
A1: Setting | B1: Value | C1: Notes
A2: Random Seed | B2: 20260903 | C2: Deterministic generation
A3: Total Transactions | B3: 3500 | C3: Main valid dataset
A4: Personal Target | B4: 1167 | C4: Minimum requested 1000
A5: Group Target | B5: 1167 | C5: Minimum requested 1000
A6: Business Target | B6: 1166 | C6: Minimum requested 1000
A7: Currency | B7: INR | C7: Change if a test moment uses another currency
A8: Money Tolerance | B8: 0.01 | C8: PASS tolerance for reconciliation
A9: Starter Create p95 Threshold ms | B9: 2000 | C9: Editable test threshold, not a product SLA
A10: Starter Read/Refresh p95 Threshold ms | B10: 2000 | C10: Editable test threshold, not a product SLA
A11: Max p95 Degradation vs Baseline | B11: 0.3 | C11: Editable threshold
A12: Max Error Rate | B12: 0.01 | C12: Editable threshold

Sheet QuickAdd_Catalog
A1: Mode | B1: Family | C1: Moment | D1: Quick_Add | E1: Semantic_Type | F1: Figma_Verification | G1: Figma_Node | H1: Target_Txn_Count | I1: Notes
A2: Personal | B2: Personal | C2: Life Operations | D2: Groceries | E2: Expense | F2: CONFIRM_FROM_FIGMA | G2: 169:487 | H2: 275 | I2: Representative label; replace with exact UI text if different.
A3: Personal | B3: Personal | C3: Life Operations | D3: Rent | E3: Expense | F3: CONFIRM_FROM_FIGMA | G3: 169:487 | H3: 275 | I3: Representative label; replace with exact UI text if different.
A4: Personal | B4: Personal | C4: Life Operations | D4: Bills | E4: Expense | F4: CONFIRM_FROM_FIGMA | G4: 169:487 | H4: 275 | I4: Representative label; replace with exact UI text if different.
A5: Personal | B5: Personal | C5: Life Operations | D5: Transport | E5: Expense | F5: CONFIRM_FROM_FIGMA | G5: 169:487 | H5: 275 | I5: Representative label; replace with exact UI text if different.
A6: Personal | B6: Personal | C6: Life Operations | D6: Healthcare | E6: Expense | F6: CONFIRM_FROM_FIGMA | G6: 169:487 | H6: 275 | I6: Representative label; replace with exact UI text if different.
A7: Personal | B7: Personal | C7: Life Operations | D7: Subscriptions | E7: Expense | F7: CONFIRM_FROM_FIGMA | G7: 169:487 | H7: 275 | I7: Representative label; replace with exact UI text if different.
A8: Personal | B8: Personal | C8: Life Operations | D8: Repairs | E8: Expense | F8: CONFIRM_FROM_FIGMA | G8: 169:487 | H8: 275 | I8: Representative label; replace with exact UI text if different.
A9: Personal | B9: Personal | C9: Future Building | D9: Savings | E9: Transfer | F9: CONFIRM_FROM_FIGMA | G9: 169:487 | H9: 275 | I9: Representative label; replace with exact UI text if different.
A10: Personal | B10: Personal | C10: Future Building | D10: Emergency Fund | E10: Transfer | F10: CONFIRM_FROM_FIGMA | G10: 169:487 | H10: 275 | I10: Representative label; replace with exact UI text if different.
A11: Personal | B11: Personal | C11: Future Building | D11: Investments | E11: Investment | F11: CONFIRM_FROM_FIGMA | G11: 169:487 | H11: 275 | I11: Representative label; replace with exact UI text if different.
A12: Personal | B12: Personal | C12: Future Building | D12: Education | E12: Expense | F12: CONFIRM_FROM_FIGMA | G12: 169:487 | H12: 275 | I12: Representative label; replace with exact UI text if different.
A13: Personal | B13: Personal | C13: Future Building | D13: Goal Contribution | E13: Transfer | F13: CONFIRM_FROM_FIGMA | G13: 169:487 | H13: 275 | I13: Representative label; replace with exact UI text if different.
... A103: Business | B103: Business | C103: Business Operations | D103: Tax | E103: Expense | F103: CONFIRM_FROM_FIGMA | G103: 169:487 | H103: 366 | I103: Representative label; replace with exact UI text if different.

Sheet Members
A1: Context | B1: Member_ID | C1: Display_Name | D1: Role | E1: Use_In_Test
A2: Personal | B2: IOS-MEM-01 | C2: IOS Santosh | D2: OWNER | E2: YES
A3: Group | B3: IOS-MEM-02 | C3: IOS Santosh | D3: OWNER | E3: YES
A4: Group | B4: IOS-MEM-03 | C4: IOS Aarav | D4: MEMBER | E4: YES
A5: Group | B5: IOS-MEM-04 | C5: IOS Meera | D5: MEMBER | E5: YES
A6: Group | B6: IOS-MEM-05 | C6: IOS Rohan | D6: MEMBER | E6: YES
A7: Group | B7: IOS-MEM-06 | C7: IOS Isha | D7: MEMBER | E7: YES
A8: Group | B8: IOS-MEM-07 | C8: IOS Vikram | D8: MEMBER | E8: YES
A9: Business | B9: IOS-MEM-08 | C9: IOS Santosh | D9: OWNER | E9: YES
A10: Business | B10: IOS-MEM-09 | C10: IOS Ops Admin | D10: ADMIN | E10: YES
A11: Business | B11: IOS-MEM-10 | C11: IOS Finance Lead | D11: ADMIN | E11: YES
A12: Business | B12: IOS-MEM-11 | C12: IOS Team Member | D12: MEMBER | E12: YES

Sheet Transactions
A1: Sequence | B1: Txn_ID | C1: Mode | D1: Family | E1: Moment | F1: Quick_Add | G1: Semantic_Type | H1: Txn_Date | I1: Txn_Time | J1: Timestamp | K1: Amount | L1: Currency | M1: Expected_Signed_Amount | N1: Paid_By | O1: Participant_Count | P1: Split_Method | Q1: Description | R1: Device_Target | S1: Run_Batch | T1: Backend_Load_Band | U1: Expected_Status | V1: Idempotency_Key
A2: 1 | B2: MTR-IOS-0001 | C2: Personal | D2: Personal | E2: Life Operations | F2: Groceries | G2: Expense | H2: 46042 | I2: 0.23650463 | J2: 46042.237 | K2: 14066.5 | L2: INR | M2: -14066.5 | N2: IOS Owner | Q2: MAESTRO-IOS-PERSONAL-LIFE_OPERATIONS-0001 | Groceries | 14066.50 | R2: iPhone | S2: B01 | T2: BASELINE_1_500 | U2: CREATED | V2: idem-20260902-ios-0001
A3: 2 | B3: MTR-IOS-0002 | C3: Group | D3: Shared Experience | E3: Trip | F3: Travel | G3: Expense | H3: 46023 | I3: 0.73158565 | J3: 46023.732 | K3: 26868.32 | L3: INR | M3: -26868.32 | N3: IOS Owner | O3: 3 | P3: EQUAL | Q3: MAESTRO-IOS-GROUP-TRIP-0002 | Travel | 26868.32 | R3: iPhone | S3: B01 | T3: BASELINE_1_500 | U3: CREATED | V3: idem-20260902-ios-0002
A4: 3 | B4: MTR-IOS-0003 | C4: Business | D4: Business | E4: Team Operations | F4: Payroll | G4: Expense | H4: 46131 | I4: 0.50604167 | J4: 46131.506 | K4: 57453.63 | L4: INR | M4: -57453.63 | N4: IOS Owner | Q4: MAESTRO-IOS-BUSINESS-TEAM_OPERATIONS-0003 | Payroll | 57453.63 | R4: iPhone | S4: B01 | T4: BASELINE_1_500 | U4: CREATED | V4: idem-20260902-ios-0003
A5: 4 | B5: MTR-IOS-0004 | C5: Personal | D5: Personal | E5: Life Operations | F5: Rent | G5: Expense | H5: 46167 | I5: 0.18815972 | J5: 46167.188 | K5: 2414.9 | L5: INR | M5: -2414.9 | N5: IOS Owner | Q5: MAESTRO-IOS-PERSONAL-LIFE_OPERATIONS-0004 | Rent | 2414.90 | R5: iPhone | S5: B01 | T5: BASELINE_1_500 | U5: CREATED | V5: idem-20260902-ios-0004
A6: 5 | B6: MTR-IOS-0005 | C6: Group | D6: Shared Experience | E6: Trip | F6: Stay | G6: Expense | H6: 46231 | I6: 0.34469907 | J6: 46231.345 | K6: 18351.21 | L6: INR | M6: -18351.21 | N6: IOS Aarav | O6: 3 | P6: PERCENTAGE | Q6: MAESTRO-IOS-GROUP-TRIP-0005 | Stay | 18351.21 | R6: iPhone | S6: B01 | T6: BASELINE_1_500 | U6: CREATED | V6: idem-20260902-ios-0005
A7: 6 | B7: MTR-IOS-0006 | C7: Business | D7: Business | E7: Team Operations | F7: Contractor | G7: Expense | H7: 45913 | I7: 0.41313657 | J7: 45913.413 | K7: 109737.08 | L7: INR | M7: -109737.08 | N7: IOS Owner | Q7: MAESTRO-IOS-BUSINESS-TEAM_OPERATIONS-0006 | Contractor | 109737.08 | R7: iPhone | S7: B01 | T7: BASELINE_1_500 | U7: CREATED | V7: idem-20260902-ios-0006
A8: 7 | B8: MTR-IOS-0007 | C8: Personal | D8: Personal | E8: Life Operations | F8: Bills | G8: Expense | H8: 46044 | I8: 0.10094907 | J8: 46044.101 | K8: 7285.65 | L8: INR | M8: -7285.65 | N8: IOS Owner | Q8: MAESTRO-IOS-PERSONAL-LIFE_OPERATIONS-0007 | Bills | 7285.65 | R8: iPhone | S8: B01 | T8: BASELINE_1_500 | U8: CREATED | V8: idem-20260902-ios-0007
A9: 8 | B9: MTR-IOS-0008 | C9: Group | D9: Shared Experience | E9: Trip | F9: Food | G9: Expense | H9: 45963 | I9: 0.39880787 | J9: 45963.399 | K9: 25422.15 | L9: INR | M9: -25422.15 | N9: IOS Meera | O9: 3 | P9: EXACT | Q9: MAESTRO-IOS-GROUP-TRIP-0008 | Food | 25422.15 | R9: iPhone | S9: B01 | T9: BASELINE_1_500 | U9: CREATED | V9: idem-20260902-ios-0008
A10: 9 | B10: MTR-IOS-0009 | C10: Business | D10: Business | E10: Team Operations | F10: Hiring | G10: Expense | H10: 45990 | I10: 0.35172454 | J10: 45990.352 | K10: 142974.65 | L10: INR | M10: -142974.65 | N10: IOS Owner | Q10: MAESTRO-IOS-BUSINESS-TEAM_OPERATIONS-0009 | Hiring | 142974.65 | R10: iPhone | S10: B01 | T10: BASELINE_1_500 | U10: CREATED | V10: idem-20260902-ios-0009
A11: 10 | B11: MTR-IOS-0010 | C11: Personal | D11: Personal | E11: Life Operations | F11: Transport | G11: Expense | H11: 45975 | I11: 0.913125 | J11: 45975.913 | K11: 13838.38 | L11: INR | M11: -13838.38 | N11: IOS Owner | Q11: MAESTRO-IOS-PERSONAL-LIFE_OPERATIONS-0010 | Transport | 13838.38 | R11: iPhone | S11: B01 | T11: BASELINE_1_500 | U11: CREATED | V11: idem-20260902-ios-0010
A12: 11 | B12: MTR-IOS-0011 | C12: Group | D12: Shared Experience | E12: Trip | F12: Local Transport | G12: Expense | H12: 46193 | I12: 0.053483796 | J12: 46193.053 | K12: 20814.45 | L12: INR | M12: -20814.45 | N12: IOS Owner | O12: 3 | P12: SHARES | Q12: MAESTRO-IOS-GROUP-TRIP-0011 | Local Transport | 20814.45 | R12: iPhone | S12: B01 | T12: BASELINE_1_500 | U12: CREATED | V12: idem-20260902-ios-0011
A13: 12 | B13: MTR-IOS-0012 | C13: Business | D13: Business | E13: Team Operations | F13: Team Meal | G13: Expense | H13: 45972 | I13: 0.72216435 | J13: 45972.722 | K13: 153816.21 | L13: INR | M13: -153816.21 | N13: IOS Owner | Q13: MAESTRO-IOS-BUSINESS-TEAM_OPERATIONS-0012 | Team Meal | 153816.21 | R13: iPhone | S13: B01 | T13: BASELINE_1_500 | U13: CREATED | V13: idem-20260902-ios-0012
A14: 13 | B14: MTR-IOS-0013 | C14: Personal | D14: Personal | E14: Life Operations | F14: Healthcare | G14: Expense | H14: 45970 | I14: 0.37262731 | J14: 45970.373 | K14: 12883.33 | L14: INR | M14: -12883.33 | N14: IOS Owner | Q14: MAESTRO-IOS-PERSONAL-LIFE_OPERATIONS-0013 | Healthcare | 12883.33 | R14: iPhone | S14: B01 | T14: BASELINE_1_500 | U14: CREATED | V14: idem-20260902-ios-0013
A15: 14 | B15: MTR-IOS-0014 | C15: Group | D15: Shared Experience | E15: Trip | F15: Activities | G15: Expense | H15: 46176 | I15: 0.03525463 | J15: 46176.035 | K15: 8585.78 | L15: INR | M15: -8585.78 | N15: IOS Aarav | O15: 3 | P15: EQUAL | Q15: MAESTRO-IOS-GROUP-TRIP-0014 | Activities | 8585.78 | R15: iPhone | S15: B01 | T15: BASELINE_1_500 | U15: CREATED | V15: idem-20260902-ios-0014
A16: 15 | B16: MTR-IOS-0015 | C16: Business | D16: Business | E16: Team Operations | F16: Travel | G16: Expense | H16: 46115 | I16: 0.20310185 | J16: 46115.203 | K16: 126238.94 | L16: INR | M16: -126238.94 | N16: IOS Owner | Q16: MAESTRO-IOS-BUSINESS-TEAM_OPERATIONS-0015 | Travel | 126238.94 | R16: iPhone | S16: B01 | T16: BASELINE_1_500 | U16: CREATED | V16: idem-20260902-ios-0015
A17: 16 | B17: MTR-IOS-0016 | C17: Personal | D17: Personal | E17: Life Operations | F17: Subscriptions | G17: Expense | H17: 46010 | I17: 0.6559375 | J17: 46010.656 | K17: 12564.33 | L17: INR | M17: -12564.33 | N17: IOS Owner | Q17: MAESTRO-IOS-PERSONAL-LIFE_OPERATIONS-0016 | Subscriptions | 12564.33 | R17: iPhone | S17: B01 | T17: BASELINE_1_500 | U17: CREATED | V17: idem-20260902-ios-0016
A18: 17 | B18: MTR-IOS-0017 | C18: Group | D18: Shared Experience | E18: Trip | F18: Shopping | G18: Expense | H18: 46216 | I18: 0.7216088 | J18: 46216.722 | K18: 14891.49 | L18: INR | M18: -14891.49 | N18: IOS Meera | O18: 3 | P18: PERCENTAGE | Q18: MAESTRO-IOS-GROUP-TRIP-0017 | Shopping | 14891.49 | R18: iPhone | S18: B01 | T18: BASELINE_1_500 | U18: CREATED | V18: idem-20260902-ios-0017
A19: 18 | B19: MTR-IOS-0018 | C19: Business | D19: Business | E19: Team Operations | F19: Training | G19: Expense | H19: 45997 | I19: 0.89090278 | J19: 45997.891 | K19: 77896.48 | L19: INR | M19: -77896.48 | N19: IOS Owner | Q19: MAESTRO-IOS-BUSINESS-TEAM_OPERATIONS-0018 | Training | 77896.48 | R19: iPhone | S19: B01 | T19: BASELINE_1_500 | U19: CREATED | V19: idem-20260902-ios-0018
A20: 19 | B20: MTR-IOS-0019 | C20: Personal | D20: Personal | E20: Life Operations | F20: Repairs | G20: Expense | H20: 46026 | I20: 0.53804398 | J20: 46026.538 | K20: 17848.59 | L20: INR | M20: -17848.59 | N20: IOS Owner | Q20: MAESTRO-IOS-PERSONAL-LIFE_OPERATIONS-0019 | Repairs | 17848.59 | R20: iPhone | S20: B01 | T20: BASELINE_1_500 | U20: CREATED | V20: idem-20260902-ios-0019
A21: 20 | B21: MTR-IOS-0020 | C21: Group | D21: Shared Experience | E21: Trip | F21: Other | G21: Expense | H21: 46213 | I21: 0.11194444 | J21: 46213.112 | K21: 16125.67 | L21: INR | M21: -16125.67 | N21: IOS Owner | O21: 3 | P21: EXACT | Q21: MAESTRO-IOS-GROUP-TRIP-0020 | Other | 16125.67 | R21: iPhone | S21: B01 | T21: BASELINE_1_500 | U21: CREATED | V21: idem-20260902-ios-0020
A22: 21 | B22: MTR-IOS-0021 | C22: Business | D22: Business | E22: Team Operations | F22: Tools | G22: Expense | H22: 46264 | I22: 0.87739583 | J22: 46264.877 | K22: 135446.27 | L22: INR | M22: -135446.27 | N22: IOS Owner | Q22: MAESTRO-IOS-BUSINESS-TEAM_OPERATIONS-0021 | Tools | 135446.27 | R22: iPhone | S22: B01 | T22: BASELINE_1_500 | U22: CREATED | V22: idem-20260902-ios-0021
A23: 22 | B23: MTR-IOS-0022 | C23: Personal | D23: Personal | E23: Future Building | F23: Savings | G23: Transfer | H23: 46252 | I23: 0.5221875 | J23: 46252.522 | K23: 16827.67 | L23: INR | M23: 0 | N23: IOS Owner | Q23: MAESTRO-IOS-PERSONAL-FUTURE_BUILDING-0022 | Savings | 16827.67 | R23: iPhone | S23: B01 | T23: BASELINE_1_500 | U23: CREATED | V23: idem-20260902-ios-0022
A24: 23 | B24: MTR-IOS-0023 | C24: Group | D24: Shared Experience | E24: Wedding | F24: Venue | G24: Expense | H24: 46174 | I24: 0.86997685 | J24: 46174.87 | K24: 24925.16 | L24: INR | M24: -24925.16 | N24: IOS Aarav | O24: 3 | P24: SHARES | Q24: MAESTRO-IOS-GROUP-WEDDING-0023 | Venue | 24925.16 | R24: iPhone | S24: B01 | T24: BASELINE_1_500 | U24: CREATED | V24: idem-20260902-ios-0023
A25: 24 | B25: MTR-IOS-0024 | C25: Business | D25: Business | E25: Business Runway | F25: Funding | G25: Income | H25: 46013 | I25: 0.52298611 | J25: 46013.523 | K25: 121141.46 | L25: INR | M25: 121141.46 | N25: IOS Owner | Q25: MAESTRO-IOS-BUSINESS-BUSINESS_RUNWAY-0024 | Funding | 121141.46 | R25: iPhone | S25: B01 | T25: BASELINE_1_500 | U25: CREATED | V25: idem-20260902-ios-0024
A26: 25 | B26: MTR-IOS-0025 | C26: Personal | D26: Personal | E26: Future Building | F26: Emergency Fund | G26: Transfer | H26: 45982 | I26: 0.12578704 | J26: 45982.126 | K26: 4005.71 | L26: INR | M26: 0 | N26: IOS Owner | Q26: MAESTRO-IOS-PERSONAL-FUTURE_BUILDING-0025 | Emergency Fund | 4005.71 | R26: iPhone | S26: B01 | T26: BASELINE_1_500 | U26: CREATED | V26: idem-20260902-ios-0025
A27: 26 | B27: MTR-IOS-0026 | C27: Group | D27: Shared Experience | E27: Wedding | F27: Catering | G27: Expense | H27: 46186 | I27: 0.51579861 | J27: 46186.516 | K27: 19704.71 | L27: INR | M27: -19704.71 | N27: IOS Meera | O27: 3 | P27: EQUAL | Q27: MAESTRO-IOS-GROUP-WEDDING-0026 | Catering | 19704.71 | R27: iPhone | S27: B01 | T27: BASELINE_1_500 | U27: CREATED | V27: idem-20260902-ios-0026
A28: 27 | B28: MTR-IOS-0027 | C28: Business | D28: Business | E28: Business Runway | F28: Revenue | G28: Income | H28: 45994 | I28: 0.25048611 | J28: 45994.25 | K28: 144069.9 | L28: INR | M28: 144069.9 | N28: IOS Owner | Q28: MAESTRO-IOS-BUSINESS-BUSINESS_RUNWAY-0027 | Revenue | 144069.90 | R28: iPhone | S28: B01 | T28: BASELINE_1_500 | U28: CREATED | V28: idem-20260902-ios-0027
A29: 28 | B29: MTR-IOS-0028 | C29: Personal | D29: Personal | E29: Future Building | F29: Investments | G29: Investment | H29: 45934 | I29: 0.94447917 | J29: 45934.944 | K29: 4161.04 | L29: INR | M29: 0 | N29: IOS Owner | Q29: MAESTRO-IOS-PERSONAL-FUTURE_BUILDING-0028 | Investments | 4161.04 | R29: iPhone | S29: B01 | T29: BASELINE_1_500 | U29: CREATED | V29: idem-20260902-ios-0028
A30: 29 | B30: MTR-IOS-0029 | C30: Group | D30: Shared Experience | E30: Wedding | F30: Decor | G30: Expense | H30: 46113 | I30: 0.66913194 | J30: 46113.669 | K30: 15620.75 | L30: INR | M30: -15620.75 | N30: IOS Owner | O30: 3 | P30: PERCENTAGE | Q30: MAESTRO-IOS-GROUP-WEDDING-0029 | Decor | 15620.75 | R30: iPhone | S30: B01 | T30: BASELINE_1_500 | U30: CREATED | V30: idem-20260902-ios-0029
A31: 30 | B31: MTR-IOS-0030 | C31: Business | D31: Business | E31: Business Runway | F31: Burn | G31: Expense | H31: 46170 | I31: 0.34246528 | J31: 46170.342 | K31: 142385.1 | L31: INR | M31: -142385.1 | N31: IOS Owner | Q31: MAESTRO-IOS-BUSINESS-BUSINESS_RUNWAY-0030 | Burn | 142385.10 | R31: iPhone | S31: B01 | T31: BASELINE_1_500 | U31: CREATED | V31: idem-20260902-ios-0030
A32: 31 | B32: MTR-IOS-0031 | C32: Personal | D32: Personal | E32: Future Building | F32: Education | G32: Expense | H32: 45931 | I32: 0.94459491 | J32: 45931.945 | K32: 6294.62 | L32: INR | M32: -6294.62 | N32: IOS Owner | Q32: MAESTRO-IOS-PERSONAL-FUTURE_BUILDING-0031 | Education | 6294.62 | R32: iPhone | S32: B01 | T32: BASELINE_1_500 | U32: CREATED | V32: idem-20260902-ios-0031
A33: 32 | B33: MTR-IOS-0032 | C33: Group | D33: Shared Experience | E33: Wedding | F33: Travel | G33: Expense | H33: 45999 | I33: 0.11041667 | J33: 45999.11 | K33: 16472.62 | L33: INR | M33: -16472.62 | N33: IOS Aarav | O33: 3 | P33: EXACT | Q33: MAESTRO-IOS-GROUP-WEDDING-0032 | Travel | 16472.62 | R33: iPhone | S33: B01 | T33: BASELINE_1_500 | U33: CREATED | V33: idem-20260902-ios-0032
A34: 33 | B34: MTR-IOS-0033 | C34: Business | D34: Business | E34: Business Runway | F34: Reserve | G34: Transfer | H34: 46079 | I34: 0.51417824 | J34: 46079.514 | K34: 827.54 | L34: INR | M34: 0 | N34: IOS Owner | Q34: MAESTRO-IOS-BUSINESS-BUSINESS_RUNWAY-0033 | Reserve | 827.54 | R34: iPhone | S34: B01 | T34: BASELINE_1_500 | U34: CREATED | V34: idem-20260902-ios-0033
A35: 34 | B35: MTR-IOS-0034 | C35: Personal | D35: Personal | E35: Future Building | F35: Goal Contribution | G35: Transfer | H35: 46192 | I35: 0.14359954 | J35: 46192.144 | K35: 10116.79 | L35: INR | M35: 0 | N35: IOS Owner | Q35: MAESTRO-IOS-PERSONAL-FUTURE_BUILDING-0034 | Goal Contribution | 10116.79 | R35: iPhone | S35: B01 | T35: BASELINE_1_500 | U35: CREATED | V35: idem-20260902-ios-0034
A36: 35 | B36: MTR-IOS-0035 | C36: Group | D36: Shared Experience | E36: Wedding | F36: Gifts | G36: Expense | H36: 45984 | I36: 0.15180556 | J36: 45984.152 | K36: 18821.96 | L36: INR | M36: -18821.96 | N36: IOS Meera | O36: 3 | P36: SHARES | Q36: MAESTRO-IOS-GROUP-WEDDING-0035 | Gifts | 18821.96 | R36: iPhone | S36: B01 | T36: BASELINE_1_500 | U36: CREATED | V36: idem-20260902-ios-0035
A37: 36 | B37: MTR-IOS-0036 | C37: Business | D37: Business | E37: Business Runway | F37: Loan | G37: Income | H37: 46087 | I37: 0.99681713 | J37: 46087.997 | K37: 122441.2 | L37: INR | M37: 122441.2 | N37: IOS Owner | Q37: MAESTRO-IOS-BUSINESS-BUSINESS_RUNWAY-0036 | Loan | 122441.20 | R37: iPhone | S37: B01 | T37: BASELINE_1_500 | U37: CREATED | V37: idem-20260902-ios-0036
A38: 37 | B38: MTR-IOS-0037 | C38: Personal | D38: Personal | E38: Lifestyle | F38: Dining | G38: Expense | H38: 46118 | I38: 0.72484954 | J38: 46118.725 | K38: 1 | L38: INR | M38: -1 | N38: IOS Owner | Q38: MAESTRO-IOS-PERSONAL-LIFESTYLE-0037 | Dining | 1.00 | R38: iPhone | S38: B01 | T38: BASELINE_1_500 | U38: CREATED | V38: idem-20260902-ios-0037
A39: 38 | B39: MTR-IOS-0038 | C39: Group | D39: Shared Experience | E39: Wedding | F39: Photography | G39: Expense | H39: 46108 | I39: 0.088055556 | J39: 46108.088 | K39: 6824.65 | L39: INR | M39: -6824.65 | N39: IOS Owner | O39: 3 | P39: EQUAL | Q39: MAESTRO-IOS-GROUP-WEDDING-0038 | Photography | 6824.65 | R39: iPhone | S39: B01 | T39: BASELINE_1_500 | U39: CREATED | V39: idem-20260902-ios-0038
A40: 39 | B40: MTR-IOS-0039 | C40: Business | D40: Business | E40: Business Runway | F40: Investment | G40: Income | H40: 46231 | I40: 0.68909722 | J40: 46231.689 | K40: 161177.11 | L40: INR | M40: 161177.11 | N40: IOS Owner | Q40: MAESTRO-IOS-BUSINESS-BUSINESS_RUNWAY-0039 | Investment | 161177.11 | R40: iPhone | S40: B01 | T40: BASELINE_1_500 | U40: CREATED | V40: idem-20260902-ios-0039
...

Sheet Group_Splits
A1: Txn_ID | B1: Moment | C1: Split_Method | D1: Member | E1: Paid_Amount | F1: Share_Amount | G1: Share_Percent | H1: Expected_Net | I1: Split_Check
A2: MTR-IOS-0002 | B2: Trip | C2: EQUAL | D2: IOS Owner | E2: 26868.32 | F2: 8956.11 | H2: 17912.21 | I2: 0
A3: MTR-IOS-0002 | B3: Trip | C3: EQUAL | D3: IOS Aarav | E3: 0 | F3: 8956.11 | H3: -8956.11 | I3: 0
A4: MTR-IOS-0002 | B4: Trip | C4: EQUAL | D4: IOS Meera | E4: 0 | F4: 8956.1 | H4: -8956.1 | I4: 0
A5: MTR-IOS-0005 | B5: Trip | C5: PERCENTAGE | D5: IOS Owner | E5: 0 | F5: 9175.61 | G5: 50 | H5: -9175.61 | I5: 0
A6: MTR-IOS-0005 | B6: Trip | C6: PERCENTAGE | D6: IOS Aarav | E6: 18351.21 | F6: 5505.36 | G6: 30 | H6: 12845.85 | I6: 0
A7: MTR-IOS-0005 | B7: Trip | C7: PERCENTAGE | D7: IOS Meera | E7: 0 | F7: 3670.24 | G7: 20 | H7: -3670.24 | I7: 0
A8: MTR-IOS-0008 | B8: Trip | C8: EXACT | D8: IOS Owner | E8: 0 | F8: 8465.58 | H8: -8465.58 | I8: 0
A9: MTR-IOS-0008 | B9: Trip | C9: EXACT | D9: IOS Aarav | E9: 0 | F9: 8465.58 | H9: -8465.58 | I9: 0
A10: MTR-IOS-0008 | B10: Trip | C10: EXACT | D10: IOS Meera | E10: 25422.15 | F10: 8490.99 | H10: 16931.16 | I10: 0
A11: MTR-IOS-0011 | B11: Trip | C11: SHARES | D11: IOS Owner | E11: 20814.45 | F11: 10407.23 | H11: 10407.22 | I11: 0
A12: MTR-IOS-0011 | B12: Trip | C12: SHARES | D12: IOS Aarav | E12: 0 | F12: 6938.15 | H12: -6938.15 | I12: 0
A13: MTR-IOS-0011 | B13: Trip | C13: SHARES | D13: IOS Meera | E13: 0 | F13: 3469.07 | H13: -3469.07 | I13: 0
A14: MTR-IOS-0014 | B14: Trip | C14: EQUAL | D14: IOS Owner | E14: 0 | F14: 2861.93 | H14: -2861.93 | I14: 0
A15: MTR-IOS-0014 | B15: Trip | C15: EQUAL | D15: IOS Aarav | E15: 8585.78 | F15: 2861.93 | H15: 5723.85 | I15: 0
A16: MTR-IOS-0014 | B16: Trip | C16: EQUAL | D16: IOS Meera | E16: 0 | F16: 2861.92 | H16: -2861.92 | I16: 0
A17: MTR-IOS-0017 | B17: Trip | C17: PERCENTAGE | D17: IOS Owner | E17: 0 | F17: 7445.75 | G17: 50 | H17: -7445.75 | I17: 0
A18: MTR-IOS-0017 | B18: Trip | C18: PERCENTAGE | D18: IOS Aarav | E18: 0 | F18: 4467.45 | G18: 30 | H18: -4467.45 | I18: 0
A19: MTR-IOS-0017 | B19: Trip | C19: PERCENTAGE | D19: IOS Meera | E19: 14891.49 | F19: 2978.29 | G19: 20 | H19: 11913.2 | I19: 0
A20: MTR-IOS-0020 | B20: Trip | C20: EXACT | D20: IOS Owner | E20: 16125.67 | F20: 5369.85 | H20: 10755.82 | I20: 0
A21: MTR-IOS-0020 | B21: Trip | C21: EXACT | D21: IOS Aarav | E21: 0 | F21: 5369.85 | H21: -5369.85 | I21: 0
A22: MTR-IOS-0020 | B22: Trip | C22: EXACT | D22: IOS Meera | E22: 0 | F22: 5385.97 | H22: -5385.97 | I22: 0
A23: MTR-IOS-0023 | B23: Wedding | C23: SHARES | D23: IOS Owner | E23: 0 | F23: 12462.58 | H23: -12462.58 | I23: 0
A24: MTR-IOS-0023 | B24: Wedding | C24: SHARES | D24: IOS Aarav | E24: 24925.16 | F24: 8308.39 | H24: 16616.77 | I24: 0
A25: MTR-IOS-0023 | B25: Wedding | C25: SHARES | D25: IOS Meera | E25: 0 | F25: 4154.19 | H25: -4154.19 | I25: 0
A26: MTR-IOS-0026 | B26: Wedding | C26: EQUAL | D26: IOS Owner | E26: 0 | F26: 6568.24 | H26: -6568.24 | I26: 0
A27: MTR-IOS-0026 | B27: Wedding | C27: EQUAL | D27: IOS Aarav | E27: 0 | F27: 6568.24 | H27: -6568.24 | I27: 0
A28: MTR-IOS-0026 | B28: Wedding | C28: EQUAL | D28: IOS Meera | E28: 19704.71 | F28: 6568.23 | H28: 13136.48 | I28: 0
A29: MTR-IOS-0029 | B29: Wedding | C29: PERCENTAGE | D29: IOS Owner | E29: 15620.75 | F29: 7810.38 | G29: 50 | H29: 7810.37 | I29: 0
A30: MTR-IOS-0029 | B30: Wedding | C30: PERCENTAGE | D30: IOS Aarav | E30: 0 | F30: 4686.23 | G30: 30 | H30: -4686.23 | I30: 0
A31: MTR-IOS-0029 | B31: Wedding | C31: PERCENTAGE | D31: IOS Meera | E31: 0 | F31: 3124.14 | G31: 20 | H31: -3124.14 | I31: 0
A32: MTR-IOS-0032 | B32: Wedding | C32: EXACT | D32: IOS Owner | E32: 0 | F32: 5485.38 | H32: -5485.38 | I32: 0
A33: MTR-IOS-0032 | B33: Wedding | C33: EXACT | D33: IOS Aarav | E33: 16472.62 | F33: 5485.38 | H33: 10987.24 | I33: 0
A34: MTR-IOS-0032 | B34: Wedding | C34: EXACT | D34: IOS Meera | E34: 0 | F34: 5501.86 | H34: -5501.86 | I34: 0
A35: MTR-IOS-0035 | B35: Wedding | C35: SHARES | D35: IOS Owner | E35: 0 | F35: 9410.98 | H35: -9410.98 | I35: 0
A36: MTR-IOS-0035 | B36: Wedding | C36: SHARES | D36: IOS Aarav | E36: 0 | F36: 6273.99 | H36: -6273.99 | I36: 0
A37: MTR-IOS-0035 | B37: Wedding | C37: SHARES | D37: IOS Meera | E37: 18821.96 | F37: 3136.99 | H37: 15684.97 | I37: 0
A38: MTR-IOS-0038 | B38: Wedding | C38: EQUAL | D38: IOS Owner | E38: 6824.65 | F38: 2274.88 | H38: 4549.77 | I38: 0
A39: MTR-IOS-0038 | B39: Wedding | C39: EQUAL | D39: IOS Aarav | E39: 0 | F39: 2274.88 | H39: -2274.88 | I39: 0
A40: MTR-IOS-0038 | B40: Wedding | C40: EQUAL | D40: IOS Meera | E40: 0 | F40: 2274.89 | H40: -2274.89 | I40: 0
...

Sheet Expected_Summary
A1: Mode | B1: Family | C1: Moment | D1: Quick_Add | E1: Expected_Count | F1: Expected_Gross_Amount | G1: Expected_Positive | H1: Expected_Expense_Absolute | I1: Expected_Net | J1: Count_Check
A2: Personal | B2: Personal | C2: Life Operations | D2: Groceries | E2: =COUNTIFS(Transactions!$C:$C,A2,Transactions!$D:$D,B2,Transactions!$E:$E,C2,Transactions!$F:$F,D2) | F2: =SUMIFS(Transactions!$K:$K,Transactions!$C:$C,A2,Transactions!$D:$D,B2,Transactions!$E:$E,C2,Transactions!$F:$F,D2) | G2: =SUMIFS(Transactions!$M:$M,Transactions!$C:$C,A2,Transactions!$D:$D,B2,Transactions!$E:$E,C2,Transactions!$F:$F,D2,Transactions!$M:$M,">0") | H2: =-SUMIFS(Transactions!$M:$M,Transactions!$C:$C,A2,Transactions!$D:$D,B2,Transactions!$E:$E,C2,Transactions!$F:$F,D2,Transactions!$M:$M,"<0") | I2: =SUMIFS(Transactions!$M:$M,Transactions!$C:$C,A2,Transactions!$D:$D,B2,Transactions!$E:$E,C2,Transactions!$F:$F,D2) | J2: =IF(E2>0,"PASS","FAIL")
A3: Personal | B3: Personal | C3: Life Operations | D3: Rent | E3: =COUNTIFS(Transactions!$C:$C,A3,Transactions!$D:$D,B3,Transactions!$E:$E,C3,Transactions!$F:$F,D3) | F3: =SUMIFS(Transactions!$K:$K,Transactions!$C:$C,A3,Transactions!$D:$D,B3,Transactions!$E:$E,C3,Transactions!$F:$F,D3) | G3: =SUMIFS(Transactions!$M:$M,Transactions!$C:$C,A3,Transactions!$D:$D,B3,Transactions!$E:$E,C3,Transactions!$F:$F,D3,Transactions!$M:$M,">0") | H3: =-SUMIFS(Transactions!$M:$M,Transactions!$C:$C,A3,Transactions!$D:$D,B3,Transactions!$E:$E,C3,Transactions!$F:$F,D3,Transactions!$M:$M,"<0") | I3: =SUMIFS(Transactions!$M:$M,Transactions!$C:$C,A3,Transactions!$D:$D,B3,Transactions!$E:$E,C3,Transactions!$F:$F,D3) | J3: =IF(E3>0,"PASS","FAIL")
A4: Personal | B4: Personal | C4: Life Operations | D4: Bills | E4: =COUNTIFS(Transactions!$C:$C,A4,Transactions!$D:$D,B4,Transactions!$E:$E,C4,Transactions!$F:$F,D4) | F4: =SUMIFS(Transactions!$K:$K,Transactions!$C:$C,A4,Transactions!$D:$D,B4,Transactions!$E:$E,C4,Transactions!$F:$F,D4) | G4: =SUMIFS(Transactions!$M:$M,Transactions!$C:$C,A4,Transactions!$D:$D,B4,Transactions!$E:$E,C4,Transactions!$F:$F,D4,Transactions!$M:$M,">0") | H4: =-SUMIFS(Transactions!$M:$M,Transactions!$C:$C,A4,Transactions!$D:$D,B4,Transactions!$E:$E,C4,Transactions!$F:$F,D4,Transactions!$M:$M,"<0") | I4: =SUMIFS(Transactions!$M:$M,Transactions!$C:$C,A4,Transactions!$D:$D,B4,Transactions!$E:$E,C4,Transactions!$F:$F,D4) | J4: =IF(E4>0,"PASS","FAIL")
A5: Personal | B5: Personal | C5: Life Operations | D5: Transport | E5: =COUNTIFS(Transactions!$C:$C,A5,Transactions!$D:$D,B5,Transactions!$E:$E,C5,Transactions!$F:$F,D5) | F5: =SUMIFS(Transactions!$K:$K,Transactions!$C:$C,A5,Transactions!$D:$D,B5,Transactions!$E:$E,C5,Transactions!$F:$F,D5) | G5: =SUMIFS(Transactions!$M:$M,Transactions!$C:$C,A5,Transactions!$D:$D,B5,Transactions!$E:$E,C5,Transactions!$F:$F,D5,Transactions!$M:$M,">0") | H5: =-SUMIFS(Transactions!$M:$M,Transactions!$C:$C,A5,Transactions!$D:$D,B5,Transactions!$E:$E,C5,Transactions!$F:$F,D5,Transactions!$M:$M,"<0") | I5: =SUMIFS(Transactions!$M:$M,Transactions!$C:$C,A5,Transactions!$D:$D,B5,Transactions!$E:$E,C5,Transactions!$F:$F,D5) | J5: =IF(E5>0,"PASS","FAIL")
A6: Personal | B6: Personal | C6: Life Operations | D6: Healthcare | E6: =COUNTIFS(Transactions!$C:$C,A6,Transactions!$D:$D,B6,Transactions!$E:$E,C6,Transactions!$F:$F,D6) | F6: =SUMIFS(Transactions!$K:$K,Transactions!$C:$C,A6,Transactions!$D:$D,B6,Transactions!$E:$E,C6,Transactions!$F:$F,D6) | G6: =SUMIFS(Transactions!$M:$M,Transactions!$C:$C,A6,Transactions!$D:$D,B6,Transactions!$E:$E,C6,Transactions!$F:$F,D6,Transactions!$M:$M,">0") | H6: =-SUMIFS(Transactions!$M:$M,Transactions!$C:$C,A6,Transactions!$D:$D,B6,Transactions!$E:$E,C6,Transactions!$F:$F,D6,Transactions!$M:$M,"<0") | I6: =SUMIFS(Transactions!$M:$M,Transactions!$C:$C,A6,Transactions!$D:$D,B6,Transactions!$E:$E,C6,Transactions!$F:$F,D6) | J6: =IF(E6>0,"PASS","FAIL")
A7: Personal | B7: Personal | C7: Life Operations | D7: Subscriptions | E7: =COUNTIFS(Transactions!$C:$C,A7,Transactions!$D:$D,B7,Transactions!$E:$E,C7,Transactions!$F:$F,D7) | F7: =SUMIFS(Transactions!$K:$K,Transactions!$C:$C,A7,Transactions!$D:$D,B7,Transactions!$E:$E,C7,Transactions!$F:$F,D7) | G7: =SUMIFS(Transactions!$M:$M,Transactions!$C:$C,A7,Transactions!$D:$D,B7,Transactions!$E:$E,C7,Transactions!$F:$F,D7,Transactions!$M:$M,">0") | H7: =-SUMIFS(Transactions!$M:$M,Transactions!$C:$C,A7,Transactions!$D:$D,B7,Transactions!$E:$E,C7,Transactions!$F:$F,D7,Transactions!$M:$M,"<0") | I7: =SUMIFS(Transactions!$M:$M,Transactions!$C:$C,A7,Transactions!$D:$D,B7,Transactions!$E:$E,C7,Transactions!$F:$F,D7) | J7: =IF(E7>0,"PASS","FAIL")
A8: Personal | B8: Personal | C8: Life Operations | D8: Repairs | E8: =COUNTIFS(Transactions!$C:$C,A8,Transactions!$D:$D,B8,Transactions!$E:$E,C8,Transactions!$F:$F,D8) | F8: =SUMIFS(Transactions!$K:$K,Transactions!$C:$C,A8,Transactions!$D:$D,B8,Transactions!$E:$E,C8,Transactions!$F:$F,D8) | G8: =SUMIFS(Transactions!$M:$M,Transactions!$C:$C,A8,Transactions!$D:$D,B8,Transactions!$E:$E,C8,Transactions!$F:$F,D8,Transactions!$M:$M,">0") | H8: =-SUMIFS(Transactions!$M:$M,Transactions!$C:$C,A8,Transactions!$D:$D,B8,Transactions!$E:$E,C8,Transactions!$F:$F,D8,Transactions!$M:$M,"<0") | I8: =SUMIFS(Transactions!$M:$M,Transactions!$C:$C,A8,Transactions!$D:$D,B8,Transactions!$E:$E,C8,Transactions!$F:$F,D8) | J8: =IF(E8>0,"PASS","FAIL")
A9: Personal | B9: Personal | C9: Future Building | D9: Savings | E9: =COUNTIFS(Transactions!$C:$C,A9,Transactions!$D:$D,B9,Transactions!$E:$E,C9,Transactions!$F:$F,D9) | F9: =SUMIFS(Transactions!$K:$K,Transactions!$C:$C,A9,Transactions!$D:$D,B9,Transactions!$E:$E,C9,Transactions!$F:$F,D9) | G9: =SUMIFS(Transactions!$M:$M,Transactions!$C:$C,A9,Transactions!$D:$D,B9,Transactions!$E:$E,C9,Transactions!$F:$F,D9,Transactions!$M:$M,">0") | H9: =-SUMIFS(Transactions!$M:$M,Transactions!$C:$C,A9,Transactions!$D:$D,B9,Transactions!$E:$E,C9,Transactions!$F:$F,D9,Transactions!$M:$M,"<0") | I9: =SUMIFS(Transactions!$M:$M,Transactions!$C:$C,A9,Transactions!$D:$D,B9,Transactions!$E:$E,C9,Transactions!$F:$F,D9) | J9: =IF(E9>0,"PASS","FAIL")
A10: Personal | B10: Personal | C10: Future Building | D10: Emergency Fund | E10: =COUNTIFS(Transactions!$C:$C,A10,Transactions!$D:$D,B10,Transactions!$E:$E,C10,Transactions!$F:$F,D10) | F10: =SUMIFS(Transactions!$K:$K,Transactions!$C:$C,A10,Transactions!$D:$D,B10,Transactions!$E:$E,C10,Transactions!$F:$F,D10) | G10: =SUMIFS(Transactions!$M:$M,Transactions!$C:$C,A10,Transactions!$D:$D,B10,Transactions!$E:$E,C10,Transactions!$F:$F,D10,Transactions!$M:$M,">0") | H10: =-SUMIFS(Transactions!$M:$M,Transactions!$C:$C,A10,Transactions!$D:$D,B10,Transactions!$E:$E,C10,Transactions!$F:$F,D10,Transactions!$M:$M,"<0") | I10: =SUMIFS(Transactions!$M:$M,Transactions!$C:$C,A10,Transactions!$D:$D,B10,Transactions!$E:$E,C10,Transactions!$F:$F,D10) | J10: =IF(E10>0,"PASS","FAIL")
A11: Personal | B11: Personal | C11: Future Building | D11: Investments | E11: =COUNTIFS(Transactions!$C:$C,A11,Transactions!$D:$D,B11,Transactions!$E:$E,C11,Transactions!$F:$F,D11) | F11: =SUMIFS(Transactions!$K:$K,Transactions!$C:$C,A11,Transactions!$D:$D,B11,Transactions!$E:$E,C11,Transactions!$F:$F,D11) | G11: =SUMIFS(Transactions!$M:$M,Transactions!$C:$C,A11,Transactions!$D:$D,B11,Transactions!$E:$E,C11,Transactions!$F:$F,D11,Transactions!$M:$M,">0") | H11: =-SUMIFS(Transactions!$M:$M,Transactions!$C:$C,A11,Transactions!$D:$D,B11,Transactions!$E:$E,C11,Transactions!$F:$F,D11,Transactions!$M:$M,"<0") | I11: =SUMIFS(Transactions!$M:$M,Transactions!$C:$C,A11,Transactions!$D:$D,B11,Transactions!$E:$E,C11,Transactions!$F:$F,D11) | J11: =IF(E11>0,"PASS","FAIL")
A12: Personal | B12: Personal | C12: Future Building | D12: Education | E12: =COUNTIFS(Transactions!$C:$C,A12,Transactions!$D:$D,B12,Transactions!$E:$E,C12,Transactions!$F:$F,D12) | F12: =SUMIFS(Transactions!$K:$K,Transactions!$C:$C,A12,Transactions!$D:$D,B12,Transactions!$E:$E,C12,Transactions!$F:$F,D12) | G12: =SUMIFS(Transactions!$M:$M,Transactions!$C:$C,A12,Transactions!$D:$D,B12,Transactions!$E:$E,C12,Transactions!$F:$F,D12,Transactions!$M:$M,">0") | H12: =-SUMIFS(Transactions!$M:$M,Transactions!$C:$C,A12,Transactions!$D:$D,B12,Transactions!$E:$E,C12,Transactions!$F:$F,D12,Transactions!$M:$M,"<0") | I12: =SUMIFS(Transactions!$M:$M,Transactions!$C:$C,A12,Transactions!$D:$D,B12,Transactions!$E:$E,C12,Transactions!$F:$F,D12) | J12: =IF(E12>0,"PASS","FAIL")
A13: Personal | B13: Personal | C13: Future Building | D13: Goal Contribution | E13: =COUNTIFS(Transactions!$C:$C,A13,Transactions!$D:$D,B13,Transactions!$E:$E,C13,Transactions!$F:$F,D13) | F13: =SUMIFS(Transactions!$K:$K,Transactions!$C:$C,A13,Transactions!$D:$D,B13,Transactions!$E:$E,C13,Transactions!$F:$F,D13) | G13: =SUMIFS(Transactions!$M:$M,Transactions!$C:$C,A13,Transactions!$D:$D,B13,Transactions!$E:$E,C13,Transactions!$F:$F,D13,Transactions!$M:$M,">0") | H13: =-SUMIFS(Transactions!$M:$M,Transactions!$C:$C,A13,Transactions!$D:$D,B13,Transactions!$E:$E,C13,Transactions!$F:$F,D13,Transactions!$M:$M,"<0") | I13: =SUMIFS(Transactions!$M:$M,Transactions!$C:$C,A13,Transactions!$D:$D,B13,Transactions!$E:$E,C13,Transactions!$F:$F,D13) | J13: =IF(E13>0,"PASS","FAIL")
... A103: Business | B103: Business | C103: Business Operations | D103: Tax | E103: =COUNTIFS(Transactions!$C:$C,A103,Transactions!$D:$D,B103,Transactions!$E:$E,C103,Transactions!$F:$F,D103) | F103: =SUMIFS(Transactions!$K:$K,Transactions!$C:$C,A103,Transactions!$D:$D,B103,Transactions!$E:$E,C103,Transactions!$F:$F,D103) | G103: =SUMIFS(Transactions!$M:$M,Transactions!$C:$C,A103,Transactions!$D:$D,B103,Transactions!$E:$E,C103,Transactions!$F:$F,D103,Transactions!$M:$M,">0") | H103: =-SUMIFS(Transactions!$M:$M,Transactions!$C:$C,A103,Transactions!$D:$D,B103,Transactions!$E:$E,C103,Transactions!$F:$F,D103,Transactions!$M:$M,"<0") | I103: =SUMIFS(Transactions!$M:$M,Transactions!$C:$C,A103,Transactions!$D:$D,B103,Transactions!$E:$E,C103,Transactions!$F:$F,D103) | J103: =IF(E103>0,"PASS","FAIL")

Sheet Reconciliation
A1: Mode | B1: Family | C1: Moment | D1: Expected_Count | E1: Actual_Count | F1: Count_Variance | G1: Expected_Gross | H1: Actual_Gross | I1: Gross_Variance | J1: Expected_Net | K1: Actual_Net | L1: Net_Variance | M1: Tolerance | N1: Result | O1: Notes
A2: Personal | B2: Personal | C2: Life Operations | D2: =COUNTIFS(Transactions!$C:$C,A2,Transactions!$D:$D,B2,Transactions!$E:$E,C2) | F2: =IF(E2="","",E2-D2) | G2: =SUMIFS(Transactions!$K:$K,Transactions!$C:$C,A2,Transactions!$D:$D,B2,Transactions!$E:$E,C2) | I2: =IF(H2="","",H2-G2) | J2: =SUMIFS(Transactions!$M:$M,Transactions!$C:$C,A2,Transactions!$D:$D,B2,Transactions!$E:$E,C2) | L2: =IF(K2="","",K2-J2) | M2: =Config!$B$8 | N2: =IF(OR(E2="",H2="",K2=""),"PENDING",IF(AND(F2=0,ABS(I2)<=M2,ABS(L2)<=M2),"PASS","FAIL")) | O2: Paste actual values from API/UI/export
A3: Personal | B3: Personal | C3: Future Building | D3: =COUNTIFS(Transactions!$C:$C,A3,Transactions!$D:$D,B3,Transactions!$E:$E,C3) | F3: =IF(E3="","",E3-D3) | G3: =SUMIFS(Transactions!$K:$K,Transactions!$C:$C,A3,Transactions!$D:$D,B3,Transactions!$E:$E,C3) | I3: =IF(H3="","",H3-G3) | J3: =SUMIFS(Transactions!$M:$M,Transactions!$C:$C,A3,Transactions!$D:$D,B3,Transactions!$E:$E,C3) | L3: =IF(K3="","",K3-J3) | M3: =Config!$B$8 | N3: =IF(OR(E3="",H3="",K3=""),"PENDING",IF(AND(F3=0,ABS(I3)<=M3,ABS(L3)<=M3),"PASS","FAIL")) | O3: Paste actual values from API/UI/export
A4: Personal | B4: Personal | C4: Lifestyle | D4: =COUNTIFS(Transactions!$C:$C,A4,Transactions!$D:$D,B4,Transactions!$E:$E,C4) | F4: =IF(E4="","",E4-D4) | G4: =SUMIFS(Transactions!$K:$K,Transactions!$C:$C,A4,Transactions!$D:$D,B4,Transactions!$E:$E,C4) | I4: =IF(H4="","",H4-G4) | J4: =SUMIFS(Transactions!$M:$M,Transactions!$C:$C,A4,Transactions!$D:$D,B4,Transactions!$E:$E,C4) | L4: =IF(K4="","",K4-J4) | M4: =Config!$B$8 | N4: =IF(OR(E4="",H4="",K4=""),"PENDING",IF(AND(F4=0,ABS(I4)<=M4,ABS(L4)<=M4),"PASS","FAIL")) | O4: Paste actual values from API/UI/export
A5: Personal | B5: Personal | C5: Relationships | D5: =COUNTIFS(Transactions!$C:$C,A5,Transactions!$D:$D,B5,Transactions!$E:$E,C5) | F5: =IF(E5="","",E5-D5) | G5: =SUMIFS(Transactions!$K:$K,Transactions!$C:$C,A5,Transactions!$D:$D,B5,Transactions!$E:$E,C5) | I5: =IF(H5="","",H5-G5) | J5: =SUMIFS(Transactions!$M:$M,Transactions!$C:$C,A5,Transactions!$D:$D,B5,Transactions!$E:$E,C5) | L5: =IF(K5="","",K5-J5) | M5: =Config!$B$8 | N5: =IF(OR(E5="",H5="",K5=""),"PENDING",IF(AND(F5=0,ABS(I5)<=M5,ABS(L5)<=M5),"PASS","FAIL")) | O5: Paste actual values from API/UI/export
A6: Group | B6: Shared Experience | C6: Trip | D6: =COUNTIFS(Transactions!$C:$C,A6,Transactions!$D:$D,B6,Transactions!$E:$E,C6) | F6: =IF(E6="","",E6-D6) | G6: =SUMIFS(Transactions!$K:$K,Transactions!$C:$C,A6,Transactions!$D:$D,B6,Transactions!$E:$E,C6) | I6: =IF(H6="","",H6-G6) | J6: =SUMIFS(Transactions!$M:$M,Transactions!$C:$C,A6,Transactions!$D:$D,B6,Transactions!$E:$E,C6) | L6: =IF(K6="","",K6-J6) | M6: =Config!$B$8 | N6: =IF(OR(E6="",H6="",K6=""),"PENDING",IF(AND(F6=0,ABS(I6)<=M6,ABS(L6)<=M6),"PASS","FAIL")) | O6: Paste actual values from API/UI/export
A7: Group | B7: Shared Experience | C7: Wedding | D7: =COUNTIFS(Transactions!$C:$C,A7,Transactions!$D:$D,B7,Transactions!$E:$E,C7) | F7: =IF(E7="","",E7-D7) | G7: =SUMIFS(Transactions!$K:$K,Transactions!$C:$C,A7,Transactions!$D:$D,B7,Transactions!$E:$E,C7) | I7: =IF(H7="","",H7-G7) | J7: =SUMIFS(Transactions!$M:$M,Transactions!$C:$C,A7,Transactions!$D:$D,B7,Transactions!$E:$E,C7) | L7: =IF(K7="","",K7-J7) | M7: =Config!$B$8 | N7: =IF(OR(E7="",H7="",K7=""),"PENDING",IF(AND(F7=0,ABS(I7)<=M7,ABS(L7)<=M7),"PASS","FAIL")) | O7: Paste actual values from API/UI/export
A8: Group | B8: Shared Experience | C8: Office Outing | D8: =COUNTIFS(Transactions!$C:$C,A8,Transactions!$D:$D,B8,Transactions!$E:$E,C8) | F8: =IF(E8="","",E8-D8) | G8: =SUMIFS(Transactions!$K:$K,Transactions!$C:$C,A8,Transactions!$D:$D,B8,Transactions!$E:$E,C8) | I8: =IF(H8="","",H8-G8) | J8: =SUMIFS(Transactions!$M:$M,Transactions!$C:$C,A8,Transactions!$D:$D,B8,Transactions!$E:$E,C8) | L8: =IF(K8="","",K8-J8) | M8: =Config!$B$8 | N8: =IF(OR(E8="",H8="",K8=""),"PENDING",IF(AND(F8=0,ABS(I8)<=M8,ABS(L8)<=M8),"PASS","FAIL")) | O8: Paste actual values from API/UI/export
A9: Group | B9: Shared Experience | C9: House Party | D9: =COUNTIFS(Transactions!$C:$C,A9,Transactions!$D:$D,B9,Transactions!$E:$E,C9) | F9: =IF(E9="","",E9-D9) | G9: =SUMIFS(Transactions!$K:$K,Transactions!$C:$C,A9,Transactions!$D:$D,B9,Transactions!$E:$E,C9) | I9: =IF(H9="","",H9-G9) | J9: =SUMIFS(Transactions!$M:$M,Transactions!$C:$C,A9,Transactions!$D:$D,B9,Transactions!$E:$E,C9) | L9: =IF(K9="","",K9-J9) | M9: =Config!$B$8 | N9: =IF(OR(E9="",H9="",K9=""),"PENDING",IF(AND(F9=0,ABS(I9)<=M9,ABS(L9)<=M9),"PASS","FAIL")) | O9: Paste actual values from API/UI/export
A10: Group | B10: Shared Purchase | C10: Gift Pool | D10: =COUNTIFS(Transactions!$C:$C,A10,Transactions!$D:$D,B10,Transactions!$E:$E,C10) | F10: =IF(E10="","",E10-D10) | G10: =SUMIFS(Transactions!$K:$K,Transactions!$C:$C,A10,Transactions!$D:$D,B10,Transactions!$E:$E,C10) | I10: =IF(H10="","",H10-G10) | J10: =SUMIFS(Transactions!$M:$M,Transactions!$C:$C,A10,Transactions!$D:$D,B10,Transactions!$E:$E,C10) | L10: =IF(K10="","",K10-J10) | M10: =Config!$B$8 | N10: =IF(OR(E10="",H10="",K10=""),"PENDING",IF(AND(F10=0,ABS(I10)<=M10,ABS(L10)<=M10),"PASS","FAIL")) | O10: Paste actual values from API/UI/export
A11: Group | B11: Shared Purchase | C11: Purchase | D11: =COUNTIFS(Transactions!$C:$C,A11,Transactions!$D:$D,B11,Transactions!$E:$E,C11) | F11: =IF(E11="","",E11-D11) | G11: =SUMIFS(Transactions!$K:$K,Transactions!$C:$C,A11,Transactions!$D:$D,B11,Transactions!$E:$E,C11) | I11: =IF(H11="","",H11-G11) | J11: =SUMIFS(Transactions!$M:$M,Transactions!$C:$C,A11,Transactions!$D:$D,B11,Transactions!$E:$E,C11) | L11: =IF(K11="","",K11-J11) | M11: =Config!$B$8 | N11: =IF(OR(E11="",H11="",K11=""),"PENDING",IF(AND(F11=0,ABS(I11)<=M11,ABS(L11)<=M11),"PASS","FAIL")) | O11: Paste actual values from API/UI/export
A12: Group | B12: Shared Purchase | C12: Assets | D12: =COUNTIFS(Transactions!$C:$C,A12,Transactions!$D:$D,B12,Transactions!$E:$E,C12) | F12: =IF(E12="","",E12-D12) | G12: =SUMIFS(Transactions!$K:$K,Transactions!$C:$C,A12,Transactions!$D:$D,B12,Transactions!$E:$E,C12) | I12: =IF(H12="","",H12-G12) | J12: =SUMIFS(Transactions!$M:$M,Transactions!$C:$C,A12,Transactions!$D:$D,B12,Transactions!$E:$E,C12) | L12: =IF(K12="","",K12-J12) | M12: =Config!$B$8 | N12: =IF(OR(E12="",H12="",K12=""),"PENDING",IF(AND(F12=0,ABS(I12)<=M12,ABS(L12)<=M12),"PASS","FAIL")) | O12: Paste actual values from API/UI/export
A13: Group | B13: Shared Purchase | C13: Custom Purchase | D13: =COUNTIFS(Transactions!$C:$C,A13,Transactions!$D:$D,B13,Transactions!$E:$E,C13) | F13: =IF(E13="","",E13-D13) | G13: =SUMIFS(Transactions!$K:$K,Transactions!$C:$C,A13,Transactions!$D:$D,B13,Transactions!$E:$E,C13) | I13: =IF(H13="","",H13-G13) | J13: =SUMIFS(Transactions!$M:$M,Transactions!$C:$C,A13,Transactions!$D:$D,B13,Transactions!$E:$E,C13) | L13: =IF(K13="","",K13-J13) | M13: =Config!$B$8 | N13: =IF(OR(E13="",H13="",K13=""),"PENDING",IF(AND(F13=0,ABS(I13)<=M13,ABS(L13)<=M13),"PASS","FAIL")) | O13: Paste actual values from API/UI/export
... A20: Business | B20: Business | C20: Business Operations | D20: =COUNTIFS(Transactions!$C:$C,A20,Transactions!$D:$D,B20,Transactions!$E:$E,C20) | F20: =IF(E20="","",E20-D20) | G20: =SUMIFS(Transactions!$K:$K,Transactions!$C:$C,A20,Transactions!$D:$D,B20,Transactions!$E:$E,C20) | I20: =IF(H20="","",H20-G20) | J20: =SUMIFS(Transactions!$M:$M,Transactions!$C:$C,A20,Transactions!$D:$D,B20,Transactions!$E:$E,C20) | L20: =IF(K20="","",K20-J20) | M20: =Config!$B$8 | N20: =IF(OR(E20="",H20="",K20=""),"PENDING",IF(AND(F20=0,ABS(I20)<=M20,ABS(L20)<=M20),"PASS","FAIL")) | O20: Paste actual values from API/UI/export

Sheet Maestro_Run
A1: Sequence | B1: Txn_ID | C1: Device | D1: Mode | E1: Family | F1: Moment | G1: Quick_Add | H1: UI_Path | I1: Amount | J1: Expected_Assertion | K1: Run_Status | L1: UI_Duration_ms | M1: API_Duration_ms | N1: HTTP_Status | O1: Backend_Txn_ID | P1: Retry_Count | Q1: Observed_Count_After | R1: Notes
A2: 1 | B2: MTR-IOS-0001 | C2: iPhone | D2: Personal | E2: Personal | F2: Life Operations | G2: Groceries | H2: Personal > Life Operations > Quick Add > Groceries | I2: 14066.5 | J2: Created MTR-IOS-0001 and correlation note visible in Activity/Pulse | K2: NOT_RUN | P2: 0 | Q2: 1
A3: 2 | B3: MTR-IOS-0002 | C3: iPhone | D3: Group | E3: Shared Experience | F3: Trip | G3: Travel | H3: Group > Trip > Quick Add > Travel | I3: 26868.32 | J3: Created MTR-IOS-0002 and correlation note visible in Activity/Pulse | K3: NOT_RUN | P3: 0 | Q3: 2
A4: 3 | B4: MTR-IOS-0003 | C4: iPhone | D4: Business | E4: Business | F4: Team Operations | G4: Payroll | H4: Business > Team Operations > Quick Add > Payroll | I4: 57453.63 | J4: Created MTR-IOS-0003 and correlation note visible in Activity/Pulse | K4: NOT_RUN | P4: 0 | Q4: 3
A5: 4 | B5: MTR-IOS-0004 | C5: iPhone | D5: Personal | E5: Personal | F5: Life Operations | G5: Rent | H5: Personal > Life Operations > Quick Add > Rent | I5: 2414.9 | J5: Created MTR-IOS-0004 and correlation note visible in Activity/Pulse | K5: NOT_RUN | P5: 0 | Q5: 4
A6: 5 | B6: MTR-IOS-0005 | C6: iPhone | D6: Group | E6: Shared Experience | F6: Trip | G6: Stay | H6: Group > Trip > Quick Add > Stay | I6: 18351.21 | J6: Created MTR-IOS-0005 and correlation note visible in Activity/Pulse | K6: NOT_RUN | P6: 0 | Q6: 5
A7: 6 | B7: MTR-IOS-0006 | C7: iPhone | D7: Business | E7: Business | F7: Team Operations | G7: Contractor | H7: Business > Team Operations > Quick Add > Contractor | I7: 109737.08 | J7: Created MTR-IOS-0006 and correlation note visible in Activity/Pulse | K7: NOT_RUN | P7: 0 | Q7: 6
A8: 7 | B8: MTR-IOS-0007 | C8: iPhone | D8: Personal | E8: Personal | F8: Life Operations | G8: Bills | H8: Personal > Life Operations > Quick Add > Bills | I8: 7285.65 | J8: Created MTR-IOS-0007 and correlation note visible in Activity/Pulse | K8: NOT_RUN | P8: 0 | Q8: 7
A9: 8 | B9: MTR-IOS-0008 | C9: iPhone | D9: Group | E9: Shared Experience | F9: Trip | G9: Food | H9: Group > Trip > Quick Add > Food | I9: 25422.15 | J9: Created MTR-IOS-0008 and correlation note visible in Activity/Pulse | K9: NOT_RUN | P9: 0 | Q9: 8
A10: 9 | B10: MTR-IOS-0009 | C10: iPhone | D10: Business | E10: Business | F10: Team Operations | G10: Hiring | H10: Business > Team Operations > Quick Add > Hiring | I10: 142974.65 | J10: Created MTR-IOS-0009 and correlation note visible in Activity/Pulse | K10: NOT_RUN | P10: 0 | Q10: 9
A11: 10 | B11: MTR-IOS-0010 | C11: iPhone | D11: Personal | E11: Personal | F11: Life Operations | G11: Transport | H11: Personal > Life Operations > Quick Add > Transport | I11: 13838.38 | J11: Created MTR-IOS-0010 and correlation note visible in Activity/Pulse | K11: NOT_RUN | P11: 0 | Q11: 10
A12: 11 | B12: MTR-IOS-0011 | C12: iPhone | D12: Group | E12: Shared Experience | F12: Trip | G12: Local Transport | H12: Group > Trip > Quick Add > Local Transport | I12: 20814.45 | J12: Created MTR-IOS-0011 and correlation note visible in Activity/Pulse | K12: NOT_RUN | P12: 0 | Q12: 11
A13: 12 | B13: MTR-IOS-0012 | C13: iPhone | D13: Business | E13: Business | F13: Team Operations | G13: Team Meal | H13: Business > Team Operations > Quick Add > Team Meal | I13: 153816.21 | J13: Created MTR-IOS-0012 and correlation note visible in Activity/Pulse | K13: NOT_RUN | P13: 0 | Q13: 12
... A3501: 3500 | B3501: MTR-IOS-3500 | C3501: iPhone | D3501: Group | E3501: Shared Experience | F3501: Trip | G3501: Other | H3501: Group > Trip > Quick Add > Other | I3501: 21962.77 | J3501: Created MTR-IOS-3500 and correlation note visible in Activity/Pulse | K3501: NOT_RUN | P3501: 0 | Q3501: 3500

Sheet Performance_Log
A1: Checkpoint_Txns | B1: Load_Band | C1: Create_p50_ms | D1: Create_p95_ms | E1: Create_p99_ms | F1: Activity_Read_p95_ms | G1: Pulse_Refresh_p95_ms | H1: DB_Query_p95_ms | I1: Error_Count | J1: Error_Rate | K1: Create_p95_Degradation_vs_Baseline | L1: Latency_Result | M1: Error_Result | N1: Overall_Result | O1: Notes
A2: 100 | B2: BASELINE_1_500 | J2: =IF(I2="","",I2/A2) | K2: =IF(OR(D2="",$D$2=""),"",D2/$D$2-1) | L2: =IF(D2="","PENDING",IF(D2<=Config!$B$9,"PASS","FAIL")) | M2: =IF(J2="","PENDING",IF(J2<=Config!$B$12,"PASS","FAIL")) | N2: =IF(OR(L2="PENDING",M2="PENDING"),"PENDING",IF(AND(L2="PASS",M2="PASS",OR(K2="",K2<=Config!$B$11)),"PASS","FAIL"))
A3: 250 | B3: BASELINE_1_500 | J3: =IF(I3="","",I3/A3) | K3: =IF(OR(D3="",$D$2=""),"",D3/$D$2-1) | L3: =IF(D3="","PENDING",IF(D3<=Config!$B$9,"PASS","FAIL")) | M3: =IF(J3="","PENDING",IF(J3<=Config!$B$12,"PASS","FAIL")) | N3: =IF(OR(L3="PENDING",M3="PENDING"),"PENDING",IF(AND(L3="PASS",M3="PASS",OR(K3="",K3<=Config!$B$11)),"PASS","FAIL"))
A4: 500 | B4: BASELINE_1_500 | J4: =IF(I4="","",I4/A4) | K4: =IF(OR(D4="",$D$2=""),"",D4/$D$2-1) | L4: =IF(D4="","PENDING",IF(D4<=Config!$B$9,"PASS","FAIL")) | M4: =IF(J4="","PENDING",IF(J4<=Config!$B$12,"PASS","FAIL")) | N4: =IF(OR(L4="PENDING",M4="PENDING"),"PENDING",IF(AND(L4="PASS",M4="PASS",OR(K4="",K4<=Config!$B$11)),"PASS","FAIL"))
A5: 1000 | B5: RAMP_501_1500 | J5: =IF(I5="","",I5/A5) | K5: =IF(OR(D5="",$D$2=""),"",D5/$D$2-1) | L5: =IF(D5="","PENDING",IF(D5<=Config!$B$9,"PASS","FAIL")) | M5: =IF(J5="","PENDING",IF(J5<=Config!$B$12,"PASS","FAIL")) | N5: =IF(OR(L5="PENDING",M5="PENDING"),"PENDING",IF(AND(L5="PASS",M5="PASS",OR(K5="",K5<=Config!$B$11)),"PASS","FAIL"))
A6: 1500 | B6: RAMP_501_1500 | J6: =IF(I6="","",I6/A6) | K6: =IF(OR(D6="",$D$2=""),"",D6/$D$2-1) | L6: =IF(D6="","PENDING",IF(D6<=Config!$B$9,"PASS","FAIL")) | M6: =IF(J6="","PENDING",IF(J6<=Config!$B$12,"PASS","FAIL")) | N6: =IF(OR(L6="PENDING",M6="PENDING"),"PENDING",IF(AND(L6="PASS",M6="PASS",OR(K6="",K6<=Config!$B$11)),"PASS","FAIL"))
A7: 2000 | B7: RAMP_1501_2500 | J7: =IF(I7="","",I7/A7) | K7: =IF(OR(D7="",$D$2=""),"",D7/$D$2-1) | L7: =IF(D7="","PENDING",IF(D7<=Config!$B$9,"PASS","FAIL")) | M7: =IF(J7="","PENDING",IF(J7<=Config!$B$12,"PASS","FAIL")) | N7: =IF(OR(L7="PENDING",M7="PENDING"),"PENDING",IF(AND(L7="PASS",M7="PASS",OR(K7="",K7<=Config!$B$11)),"PASS","FAIL"))
A8: 2500 | B8: RAMP_1501_2500 | J8: =IF(I8="","",I8/A8) | K8: =IF(OR(D8="",$D$2=""),"",D8/$D$2-1) | L8: =IF(D8="","PENDING",IF(D8<=Config!$B$9,"PASS","FAIL")) | M8: =IF(J8="","PENDING",IF(J8<=Config!$B$12,"PASS","FAIL")) | N8: =IF(OR(L8="PENDING",M8="PENDING"),"PENDING",IF(AND(L8="PASS",M8="PASS",OR(K8="",K8<=Config!$B$11)),"PASS","FAIL"))
A9: 3000 | B9: HIGH_2501_3000 | J9: =IF(I9="","",I9/A9) | K9: =IF(OR(D9="",$D$2=""),"",D9/$D$2-1) | L9: =IF(D9="","PENDING",IF(D9<=Config!$B$9,"PASS","FAIL")) | M9: =IF(J9="","PENDING",IF(J9<=Config!$B$12,"PASS","FAIL")) | N9: =IF(OR(L9="PENDING",M9="PENDING"),"PENDING",IF(AND(L9="PASS",M9="PASS",OR(K9="",K9<=Config!$B$11)),"PASS","FAIL"))
A10: 3100 | B10: STRESS_3001_3500 | J10: =IF(I10="","",I10/A10) | K10: =IF(OR(D10="",$D$2=""),"",D10/$D$2-1) | L10: =IF(D10="","PENDING",IF(D10<=Config!$B$9,"PASS","FAIL")) | M10: =IF(J10="","PENDING",IF(J10<=Config!$B$12,"PASS","FAIL")) | N10: =IF(OR(L10="PENDING",M10="PENDING"),"PENDING",IF(AND(L10="PASS",M10="PASS",OR(K10="",K10<=Config!$B$11)),"PASS","FAIL"))
A11: 3200 | B11: STRESS_3001_3500 | J11: =IF(I11="","",I11/A11) | K11: =IF(OR(D11="",$D$2=""),"",D11/$D$2-1) | L11: =IF(D11="","PENDING",IF(D11<=Config!$B$9,"PASS","FAIL")) | M11: =IF(J11="","PENDING",IF(J11<=Config!$B$12,"PASS","FAIL")) | N11: =IF(OR(L11="PENDING",M11="PENDING"),"PENDING",IF(AND(L11="PASS",M11="PASS",OR(K11="",K11<=Config!$B$11)),"PASS","FAIL"))
A12: 3300 | B12: STRESS_3001_3500 | J12: =IF(I12="","",I12/A12) | K12: =IF(OR(D12="",$D$2=""),"",D12/$D$2-1) | L12: =IF(D12="","PENDING",IF(D12<=Config!$B$9,"PASS","FAIL")) | M12: =IF(J12="","PENDING",IF(J12<=Config!$B$12,"PASS","FAIL")) | N12: =IF(OR(L12="PENDING",M12="PENDING"),"PENDING",IF(AND(L12="PASS",M12="PASS",OR(K12="",K12<=Config!$B$11)),"PASS","FAIL"))
A13: 3400 | B13: STRESS_3001_3500 | J13: =IF(I13="","",I13/A13) | K13: =IF(OR(D13="",$D$2=""),"",D13/$D$2-1) | L13: =IF(D13="","PENDING",IF(D13<=Config!$B$9,"PASS","FAIL")) | M13: =IF(J13="","PENDING",IF(J13<=Config!$B$12,"PASS","FAIL")) | N13: =IF(OR(L13="PENDING",M13="PENDING"),"PENDING",IF(AND(L13="PASS",M13="PASS",OR(K13="",K13<=Config!$B$11)),"PASS","FAIL"))
A14: 3500 | B14: STRESS_3001_3500 | J14: =IF(I14="","",I14/A14) | K14: =IF(OR(D14="",$D$2=""),"",D14/$D$2-1) | L14: =IF(D14="","PENDING",IF(D14<=Config!$B$9,"PASS","FAIL")) | M14: =IF(J14="","PENDING",IF(J14<=Config!$B$12,"PASS","FAIL")) | N14: =IF(OR(L14="PENDING",M14="PENDING"),"PENDING",IF(AND(L14="PASS",M14="PASS",OR(K14="",K14<=Config!$B$11)),"PASS","FAIL"))

Sheet Test_Cases
A1: Test_ID | B1: Area | C1: Context | D1: Scenario | E1: Steps_Summary | F1: Expected_Result | G1: Priority | H1: Device_Coverage | I1: Data_Reference | J1: Status
A2: TC-001 | B2: Quick Add | C2: All | D2: Create one record for every QuickAdd | E2: Execute one row from every QuickAdd catalog entry | F2: Record created once; Activity/Pulse reflect expected amount | G2: P0 | H2: Android+iPhone | I2: QuickAdd_Catalog | J2: NOT_RUN
A3: TC-002 | B3: Load | C3: All | D3: 3,300 interleaved creates | E3: Run Maestro_Run in sequence | F3: No missing/duplicate records; backend remains responsive | G3: P0 | H3: Android+iPhone | I3: Transactions | J3: NOT_RUN
A4: TC-003 | B4: Performance | C4: All | D4: Compare p95 at 250 vs 3,000+ | E4: Capture metrics at each checkpoint | F4: Degradation within configured threshold | G4: P0 | H4: Android+iPhone | I4: Performance_Log | J4: NOT_RUN
A5: TC-004 | B5: Idempotency | C5: All | D5: Double tap/retry same create | E5: Submit same idempotency key twice | F5: Exactly one committed transaction | G5: P0 | H5: Android+iPhone | I5: Transactions.Idempotency_Key | J5: NOT_RUN
A6: TC-005 | B6: Offline Retry | C6: All | D6: Lose network during create | E6: Create offline/weak network then restore | F6: No duplicate; clear retry/error state | G6: P1 | H6: Android+iPhone | I6: Sample 20 rows | J6: NOT_RUN
A7: TC-006 | B7: Persistence | C7: All | D7: Kill/relaunch after batches | E7: Force stop and reopen | F7: Counts/totals persist and reload correctly | G7: P0 | H7: Android+iPhone | I7: Every 500 rows | J7: NOT_RUN
A8: TC-007 | B8: Money | C8: All | D8: Decimal rounding | E8: Use 0.01, 0.99, 10.01, 99.99 amounts | F8: No floating point drift > tolerance | G8: P0 | H8: Android+iPhone | I8: Edge rows in Transactions | J8: NOT_RUN
A9: TC-008 | B9: Money | C9: All | D9: Large amount | E9: Use 100000.00+ values | F9: No overflow/truncation/formatting error | G9: P1 | H9: Android+iPhone | I9: Edge rows in Transactions | J9: NOT_RUN
A10: TC-009 | B10: Validation | C10: All | D10: Zero/negative invalid input | E10: Try zero/negative where UI forbids it | F10: Validation shown; no backend record | G10: P1 | H10: Android+iPhone | I10: Manual edge case | J10: NOT_RUN
A11: TC-010 | B11: Group Split | C11: Group | D11: Equal split | E11: Create EQUAL split records | F11: Participant shares sum to amount within 0.01 | G11: P0 | H11: Android+iPhone | I11: Group_Splits | J11: NOT_RUN
A12: TC-011 | B12: Group Split | C12: Group | D12: Exact split | E12: Create EXACT split records | F12: Exact shares sum to amount within 0.01 | G12: P0 | H12: Android+iPhone | I12: Group_Splits | J12: NOT_RUN
... A25: TC-024 | B25: Backend | C25: All | D25: Error/retry observation | E25: Record 4xx/5xx/timeouts and retries | F25: Error rate <= configured threshold; failures explainable | G25: P0 | H25: Backend | I25: Performance_Log | J25: NOT_RUN

Sheet Dashboard
A1: Momentra Load Test Dashboard | B1: Value | D1: Context | E1: Count
A2: Planned Transactions | B2: =Config!B3 | D2: Personal | E2: 1167
A3: Personal Planned | B3: =COUNTIF(Transactions!C:C,"Personal") | D3: Group | E3: 1167
A4: Group Planned | B4: =COUNTIF(Transactions!C:C,"Group") | D4: Business | E4: 1166
A5: Business Planned | B5: =COUNTIF(Transactions!C:C,"Business")
A6: iPhone Rows | B6: =COUNTIF(Transactions!R:R,"iPhone")
A7: Other Platform Rows | B7: =3500-B6
A8: Stress 3k+ Rows | B8: =COUNTIF(Transactions!T:T,"STRESS_3001_3500")
A9: Reconciliation PASS | B9: =COUNTIF(Reconciliation!N:N,"PASS")
A10: Reconciliation FAIL | B10: =COUNTIF(Reconciliation!N:N,"FAIL")
A11: Performance PASS | B11: =COUNTIF(Performance_Log!N:N,"PASS")
A12: Performance FAIL | B12: =COUNTIF(Performance_Log!N:N,"FAIL")
